<sdf version='1.11'>
  <model name='cartesian_plotter'>
    <static>true</static>
    <link name='base_link'>
      <inertial>
        <pose>0 0 0 0 0 0</pose>
        <mass>2</mass>
        <inertia>
          <ixx>1.1000000000000001</ixx>
          <ixy>0</ixy>
          <ixz>0</ixz>
          <iyy>1.1000000000000001</iyy>
          <iyz>0</iyz>
          <izz>1.1000000000000001</izz>
        </inertia>
      </inertial>
      <visual name='base_link_visual'>
        <pose>0 0 0 0 0 0</pose>
        <geometry>
          <mesh>
            <scale>0.050000000000000003 0.050000000000000003 0.050000000000000003</scale>
            <uri>file:///home/vaibhav/programming_projects/Robotics/Cartesian_ploter/Meshes/base_link_NEW.stl</uri>
          </mesh>
        </geometry>
        <material>
          <diffuse>0 0 0 1</diffuse>
          <ambient>0 0 0 1</ambient>
        </material>
      </visual>
      <visual name='base_link_fixed_joint_lump__X_Rail_visual_1'>
        <pose>0 0 0 0 0 0</pose>
        <geometry>
          <mesh>
            <scale>0.050000000000000003 0.050000000000000003 0.050000000000000003</scale>
            <uri>file:///home/vaibhav/programming_projects/Robotics/Cartesian_ploter/Meshes/x_rail_NEW.stl</uri>
          </mesh>
        </geometry>
        <material>
          <diffuse>0 0 1 1</diffuse>
          <ambient>0 0 1 1</ambient>
        </material>
      </visual>
    </link>
    <joint name='x_to_y' type='prismatic'>
      <pose relative_to='base_link'>0 0 0 0 0 0</pose>
      <parent>base_link</parent>
      <child>Y_rail</child>
      <axis>
        <xyz>1 0 0</xyz>
        <limit>
          <lower>0</lower>
          <upper>5000</upper>
          <effort>10</effort>
          <velocity>1</velocity>
        </limit>
        <dynamics>
          <spring_reference>0</spring_reference>
          <spring_stiffness>0</spring_stiffness>
        </dynamics>
      </axis>
    </joint>
    <link name='Y_rail'>
      <pose relative_to='x_to_y'>0 0 0 0 0 0</pose>
      <inertial>
        <pose>0 0 0 0 0 0</pose>
        <mass>1</mass>
        <inertia>
          <ixx>0.10000000000000001</ixx>
          <ixy>0</ixy>
          <ixz>0</ixz>
          <iyy>0.10000000000000001</iyy>
          <iyz>0</iyz>
          <izz>0.10000000000000001</izz>
        </inertia>
      </inertial>
      <visual name='Y_rail_visual'>
        <pose>0 0 0 0 0 0</pose>
        <geometry>
          <mesh>
            <scale>0.050000000000000003 0.050000000000000003 0.050000000000000003</scale>
            <uri>file:///home/vaibhav/programming_projects/Robotics/Cartesian_ploter/Meshes/y_slider_NEW.stl</uri>
          </mesh>
        </geometry>
        <material>
          <diffuse>0 0 1 1</diffuse>
          <ambient>0 0 1 1</ambient>
        </material>
      </visual>
    </link>
    <frame name='base_to_x' attached_to='base_link'>
      <pose>0 0 0 0 0 0</pose>
    </frame>
    <frame name='X_Rail' attached_to='base_to_x'>
      <pose>0 0 0 0 0 0</pose>
    </frame>
  </model>
</sdf>
