<sdf version='1.11'>
  <model name='cartesian_plotter'>
    <joint name='world_to_base' type='fixed'>
      <pose relative_to='__model__'>0 0 0 0 0 0</pose>
      <parent>world</parent>
      <child>base_link</child>
    </joint>
    <link name='base_link'>
      <pose relative_to='world_to_base'>0 0 0 0 0 0</pose>
      <inertial>
        <pose>0 0 0.0031250000000000002 0 0 0</pose>
        <mass>0.47999999999999998</mass>
        <inertia>
          <ixx>0.0160703125</ixx>
          <ixy>0</ixy>
          <ixz>0</ixz>
          <iyy>0.0160703125</iyy>
          <iyz>0</iyz>
          <izz>0.016</izz>
        </inertia>
      </inertial>
      <collision name='base_link_fixed_joint_lump__paper_collision'>
        <pose>0 0 0.050000000000000003 0 0 0</pose>
        <geometry>
          <box>
            <size>0.29699999999999999 0.20999999999999999 0.001</size>
          </box>
        </geometry>
      </collision>
      <visual name='base_link_visual'>
        <pose>0 0 0 0 0 0</pose>
        <geometry>
          <mesh>
            <scale>0.01 0.01 0.01</scale>
            <uri>file:///home/vaibhav/programming_projects/Robotics/Cartesian_ploter/Meshes/base_link_NEW.stl</uri>
          </mesh>
        </geometry>
        <material>
          <diffuse>0.187500015 0.187500015 0.187500015 1</diffuse>
          <ambient>0.187500015 0.187500015 0.187500015 1</ambient>
        </material>
      </visual>
      <visual name='base_link_fixed_joint_lump__X_Rail_visual_1'>
        <pose>-0.040000000000000001 -0.42499999999999999 0.050000000000000003 0 0 0</pose>
        <geometry>
          <mesh>
            <scale>0.01 0.01 0.01</scale>
            <uri>file:///home/vaibhav/programming_projects/Robotics/Cartesian_ploter/Meshes/x_rail_NEW.stl</uri>
          </mesh>
        </geometry>
        <material>
          <diffuse>1 1 1 1</diffuse>
          <ambient>1 1 1 1</ambient>
        </material>
      </visual>
      <visual name='base_link_fixed_joint_lump__paper_visual_2'>
        <pose>0 0 0.050000000000000003 0 0 0</pose>
        <geometry>
          <box>
            <size>0.29699999999999999 0.20999999999999999 0.001</size>
          </box>
        </geometry>
        <material>
          <diffuse>1 0 1 1</diffuse>
          <ambient>1 0 1 1</ambient>
        </material>
      </visual>
    </link>
    <joint name='x_to_y' type='prismatic'>
      <pose relative_to='base_link'>0 0 0 0 0 0</pose>
      <parent>base_link</parent>
      <child>Y_rail</child>
      <axis>
        <xyz>1 0 0</xyz>
        <limit>
          <lower>0</lower>
          <upper>0.20000000000000001</upper>
          <effort>100</effort>
          <velocity>0.20000000000000001</velocity>
        </limit>
        <dynamics>
          <spring_reference>0</spring_reference>
          <spring_stiffness>0</spring_stiffness>
        </dynamics>
      </axis>
    </joint>
    <link name='Y_rail'>
      <pose relative_to='x_to_y'>0 0 0 0 0 0</pose>
      <inertial>
        <pose>0 0 0 0 0 0</pose>
        <mass>0.14999999999999999</mass>
        <inertia>
          <ixx>0.0050000000000000001</ixx>
          <ixy>0</ixy>
          <ixz>0</ixz>
          <iyy>0.0050000000000000001</iyy>
          <iyz>0</iyz>
          <izz>0.0050000000000000001</izz>
        </inertia>
      </inertial>
      <visual name='Y_rail_visual'>
        <pose>0.029999999999999999 -0.0124 0.095000000000000001 0 0 0</pose>
        <geometry>
          <mesh>
            <scale>0.01 0.01 0.01</scale>
            <uri>file:///home/vaibhav/programming_projects/Robotics/Cartesian_ploter/Meshes/y_slider_NEW.stl</uri>
          </mesh>
        </geometry>
        <material>
          <diffuse>1 1 1 1</diffuse>
          <ambient>1 1 1 1</ambient>
        </material>
      </visual>
    </link>
    <joint name='y_and_z' type='prismatic'>
      <pose relative_to='Y_rail'>0 0 0 0 0 0</pose>
      <parent>Y_rail</parent>
      <child>z_rail</child>
      <axis>
        <xyz>0 1 0</xyz>
        <limit>
          <lower>0</lower>
          <upper>0.20000000000000001</upper>
          <effort>100</effort>
          <velocity>0.20000000000000001</velocity>
        </limit>
        <dynamics>
          <spring_reference>0</spring_reference>
          <spring_stiffness>0</spring_stiffness>
        </dynamics>
      </axis>
    </joint>
    <link name='z_rail'>
      <pose relative_to='y_and_z'>0 0 0 0 0 0</pose>
      <inertial>
        <pose>0 0 0 0 0 0</pose>
        <mass>0.14999999999999999</mass>
        <inertia>
          <ixx>0.0050000000000000001</ixx>
          <ixy>0</ixy>
          <ixz>0</ixz>
          <iyy>0.0050000000000000001</iyy>
          <iyz>0</iyz>
          <izz>0.0050000000000000001</izz>
        </inertia>
      </inertial>
      <visual name='z_rail_visual'>
        <pose>0.054710000000000002 -0.074709999999999999 0.10487 0 0 0</pose>
        <geometry>
          <mesh>
            <scale>0.01 0.01 0.01</scale>
            <uri>file:///home/vaibhav/programming_projects/Robotics/Cartesian_ploter/Meshes/z_cartilage_NEW.stl</uri>
          </mesh>
        </geometry>
        <material>
          <diffuse>0.187500015 0.187500015 0.187500015 1</diffuse>
          <ambient>0.187500015 0.187500015 0.187500015 1</ambient>
        </material>
      </visual>
    </link>
    <joint name='z_and_holder' type='prismatic'>
      <pose relative_to='z_rail'>0 0 0 0 0 0</pose>
      <parent>z_rail</parent>
      <child>pen_and_holder</child>
      <axis>
        <xyz>0 0 1</xyz>
        <limit>
          <lower>0</lower>
          <upper>0.20000000000000001</upper>
          <effort>100</effort>
          <velocity>0.20000000000000001</velocity>
        </limit>
        <dynamics>
          <spring_reference>0</spring_reference>
          <spring_stiffness>0</spring_stiffness>
        </dynamics>
      </axis>
    </joint>
    <link name='pen_and_holder'>
      <pose relative_to='z_and_holder'>0 0 0 0 0 0</pose>
      <inertial>
        <pose>0 0 0 0 0 0</pose>
        <mass>0.050000000000000003</mass>
        <inertia>
          <ixx>0.001</ixx>
          <ixy>0</ixy>
          <ixz>0</ixz>
          <iyy>0.001</iyy>
          <iyz>0</iyz>
          <izz>0.001</izz>
        </inertia>
      </inertial>
      <visual name='pen_and_holder_visual'>
        <pose>0.089700000000000002 -0.066600000000000006 0.067000000000000004 0 0 0</pose>
        <geometry>
          <mesh>
            <scale>0.01 0.01 0.01</scale>
            <uri>file:///home/vaibhav/programming_projects/Robotics/Cartesian_ploter/Meshes/pen_holder_NEW.stl</uri>
          </mesh>
        </geometry>
        <material>
          <diffuse>1 1 1 1</diffuse>
          <ambient>1 1 1 1</ambient>
        </material>
      </visual>
    </link>
    <plugin name='gz::sim::systems::JointPositionController' filename='gz-sim-joint-position-controller-system'>
      <joint_name>x_to_y</joint_name>
      <topic>/model/cartesian_plotter/joint/x_to_y/cmd_pos</topic>
      <p_gain>5</p_gain>
      <i_gain>0.0</i_gain>
      <d_gain>4.5</d_gain>
      <cmd_max>100</cmd_max>
      <cmd_min>-100</cmd_min>
    </plugin>
    <plugin name='gz::sim::systems::JointPositionController' filename='gz-sim-joint-position-controller-system'>
      <joint_name>y_and_z</joint_name>
      <topic>/model/cartesian_plotter/joint/y_and_z/cmd_pos</topic>
      <p_gain>5</p_gain>
      <i_gain>0.0</i_gain>
      <d_gain>4.5</d_gain>
      <cmd_max>100</cmd_max>
      <cmd_min>-100</cmd_min>
    </plugin>
    <plugin name='gz::sim::systems::JointPositionController' filename='gz-sim-joint-position-controller-system'>
      <joint_name>z_and_holder</joint_name>
      <topic>/model/cartesian_plotter/joint/z_and_holder/cmd_pos</topic>
      <p_gain>5</p_gain>
      <i_gain>0.0</i_gain>
      <d_gain>4.5</d_gain>
      <cmd_max>100</cmd_max>
      <cmd_min>-100</cmd_min>
    </plugin>
    <frame name='base_to_x' attached_to='base_link'>
      <pose>0 0 0 0 0 0</pose>
    </frame>
    <frame name='X_Rail' attached_to='base_to_x'>
      <pose>0 0 0 0 0 0</pose>
    </frame>
    <frame name='pen and base' attached_to='base_link'>
      <pose>0 0 0.050000000000000003 0 0 0</pose>
    </frame>
    <frame name='paper' attached_to='pen and base'>
      <pose>0 0 0 0 0 0</pose>
    </frame>
  </model>
</sdf>
